Exception on /api/login [POST]
Traceback (most recent call last):
  File "/home/wato/.local/share/virtualenvs/backend-uL66Fw_X/lib/python3.8/site-packages/flask/app.py", line 1473, in wsgi_app
    response = self.full_dispatch_request()
  File "/home/wato/.local/share/virtualenvs/backend-uL66Fw_X/lib/python3.8/site-packages/flask/app.py", line 882, in full_dispatch_request
    rv = self.handle_user_exception(e)
  File "/home/wato/.local/share/virtualenvs/backend-uL66Fw_X/lib/python3.8/site-packages/flask_cors/extension.py", line 194, in wrapped_function
    return cors_after_request(app.make_response(f(*args, **kwargs)))
  File "/home/wato/.local/share/virtualenvs/backend-uL66Fw_X/lib/python3.8/site-packages/flask/app.py", line 880, in full_dispatch_request
    rv = self.dispatch_request()
  File "/home/wato/.local/share/virtualenvs/backend-uL66Fw_X/lib/python3.8/site-packages/flask/app.py", line 865, in dispatch_request
    return self.ensure_sync(self.view_functions[rule.endpoint])(**view_args)  # type: ignore[no-any-return]
  File "/home/wato/Development/code/phase-5/project/EventYangu/backend/app/routes.py", line 45, in login
    token = create_access_token(identity=user.id)
  File "/home/wato/.local/share/virtualenvs/backend-uL66Fw_X/lib/python3.8/site-packages/flask_jwt_extended/utils.py", line 175, in create_access_token
    return jwt_manager._encode_jwt_from_config(
  File "/home/wato/.local/share/virtualenvs/backend-uL66Fw_X/lib/python3.8/site-packages/flask_jwt_extended/jwt_manager.py", line 527, in _encode_jwt_from_config
    secret=self._encode_key_callback(identity),
  File "/home/wato/.local/share/virtualenvs/backend-uL66Fw_X/lib/python3.8/site-packages/flask_jwt_extended/default_callbacks.py", line 161, in default_encode_key_callback
    return config.encode_key
  File "/home/wato/.local/share/virtualenvs/backend-uL66Fw_X/lib/python3.8/site-packages/flask_jwt_extended/config.py", line 36, in encode_key
    return self._private_key if self.is_asymmetric else self._secret_key
  File "/home/wato/.local/share/virtualenvs/backend-uL66Fw_X/lib/python3.8/site-packages/flask_jwt_extended/config.py", line 238, in _secret_key
    raise RuntimeError(
RuntimeError: JWT_SECRET_KEY or flask SECRET_KEY must be set when using symmetric algorithm "HS256"
